Traceback (most recent call last):
  File "/usr/lib/python3/dist-packages/urllib3/connection.py", line 138, in _new_conn
    (self.host, self.port), self.timeout, **extra_kw)
  File "/usr/lib/python3/dist-packages/urllib3/util/connection.py", line 98, in create_connection
    raise err
  File "/usr/lib/python3/dist-packages/urllib3/util/connection.py", line 88, in create_connection
    sock.connect(sa)
ConnectionRefusedError: [Errno 111] Connection refused

During handling of the above exception, another exception occurred:

Traceback (most recent call last):
  File "/usr/lib/python3/dist-packages/urllib3/connectionpool.py", line 594, in urlopen
    chunked=chunked)
  File "/usr/lib/python3/dist-packages/urllib3/connectionpool.py", line 361, in _make_request
    conn.request(method, url, **httplib_request_kw)
  File "/usr/lib/python3.5/http/client.py", line 1107, in request
    self._send_request(method, url, body, headers)
  File "/usr/lib/python3.5/http/client.py", line 1152, in _send_request
    self.endheaders(body)
  File "/usr/lib/python3.5/http/client.py", line 1103, in endheaders
    self._send_output(message_body)
  File "/usr/lib/python3.5/http/client.py", line 934, in _send_output
    self.send(msg)
  File "/usr/lib/python3.5/http/client.py", line 877, in send
    self.connect()
  File "/usr/lib/python3/dist-packages/urllib3/connection.py", line 163, in connect
    conn = self._new_conn()
  File "/usr/lib/python3/dist-packages/urllib3/connection.py", line 147, in _new_conn
    self, "Failed to establish a new connection: %s" % e)
urllib3.exceptions.NewConnectionError: <urllib3.connection.HTTPConnection object at 0x7fe151311e10>: Failed to establish a new connection: [Errno 111] Connection refused

During handling of the above exception, another exception occurred:

Traceback (most recent call last):
  File "tests/bugs/issue_32/bug_test_ozone_heroku_1_ws.py", line 30, in <module>
    cont = test_heroku_pyaf_2(data);
  File "tests/bugs/issue_32/bug_test_ozone_heroku_1_ws.py", line 22, in test_heroku_pyaf_2
    body=json.dumps(data))
  File "/usr/lib/python3/dist-packages/urllib3/request.py", line 70, in request
    **urlopen_kw)
  File "/usr/lib/python3/dist-packages/urllib3/request.py", line 148, in request_encode_body
    return self.urlopen(method, url, **extra_kw)
  File "/usr/lib/python3/dist-packages/urllib3/poolmanager.py", line 244, in urlopen
    response = conn.urlopen(method, u.request_uri, **kw)
  File "/usr/lib/python3/dist-packages/urllib3/connectionpool.py", line 671, in urlopen
    release_conn=release_conn, **response_kw)
  File "/usr/lib/python3/dist-packages/urllib3/connectionpool.py", line 671, in urlopen
    release_conn=release_conn, **response_kw)
  File "/usr/lib/python3/dist-packages/urllib3/connectionpool.py", line 671, in urlopen
    release_conn=release_conn, **response_kw)
  File "/usr/lib/python3/dist-packages/urllib3/connectionpool.py", line 643, in urlopen
    _stacktrace=sys.exc_info()[2])
  File "/usr/lib/python3/dist-packages/urllib3/util/retry.py", line 363, in increment
    raise MaxRetryError(_pool, url, error or ResponseError(cause))
urllib3.exceptions.MaxRetryError: HTTPConnectionPool(host='0.0.0.0', port=8081): Max retries exceeded with url: /model (Caused by NewConnectionError('<urllib3.connection.HTTPConnection object at 0x7fe151311e10>: Failed to establish a new connection: [Errno 111] Connection refused',))
