Traceback (most recent call last):
  File "/home/antoine/.local/lib/python3.6/site-packages/urllib3/connectionpool.py", line 601, in urlopen
    chunked=chunked)
  File "/home/antoine/.local/lib/python3.6/site-packages/urllib3/connectionpool.py", line 387, in _make_request
    six.raise_from(e, None)
  File "<string>", line 2, in raise_from
  File "/home/antoine/.local/lib/python3.6/site-packages/urllib3/connectionpool.py", line 383, in _make_request
    httplib_response = conn.getresponse()
  File "/usr/lib/python3.6/http/client.py", line 1331, in getresponse
    response.begin()
  File "/usr/lib/python3.6/http/client.py", line 297, in begin
    version, status, reason = self._read_status()
  File "/usr/lib/python3.6/http/client.py", line 266, in _read_status
    raise RemoteDisconnected("Remote end closed connection without"
http.client.RemoteDisconnected: Remote end closed connection without response

During handling of the above exception, another exception occurred:

Traceback (most recent call last):
  File "tests/bugs/issue_32/bug_test_ozone_heroku_1_ws.py", line 30, in <module>
    cont = test_heroku_pyaf_2(data);
  File "tests/bugs/issue_32/bug_test_ozone_heroku_1_ws.py", line 22, in test_heroku_pyaf_2
    body=json.dumps(data))
  File "/home/antoine/.local/lib/python3.6/site-packages/urllib3/request.py", line 70, in request
    **urlopen_kw)
  File "/home/antoine/.local/lib/python3.6/site-packages/urllib3/request.py", line 148, in request_encode_body
    return self.urlopen(method, url, **extra_kw)
  File "/home/antoine/.local/lib/python3.6/site-packages/urllib3/poolmanager.py", line 321, in urlopen
    response = conn.urlopen(method, u.request_uri, **kw)
  File "/home/antoine/.local/lib/python3.6/site-packages/urllib3/connectionpool.py", line 639, in urlopen
    _stacktrace=sys.exc_info()[2])
  File "/home/antoine/.local/lib/python3.6/site-packages/urllib3/util/retry.py", line 357, in increment
    raise six.reraise(type(error), error, _stacktrace)
  File "/home/antoine/.local/lib/python3.6/site-packages/urllib3/packages/six.py", line 685, in reraise
    raise value.with_traceback(tb)
  File "/home/antoine/.local/lib/python3.6/site-packages/urllib3/connectionpool.py", line 601, in urlopen
    chunked=chunked)
  File "/home/antoine/.local/lib/python3.6/site-packages/urllib3/connectionpool.py", line 387, in _make_request
    six.raise_from(e, None)
  File "<string>", line 2, in raise_from
  File "/home/antoine/.local/lib/python3.6/site-packages/urllib3/connectionpool.py", line 383, in _make_request
    httplib_response = conn.getresponse()
  File "/usr/lib/python3.6/http/client.py", line 1331, in getresponse
    response.begin()
  File "/usr/lib/python3.6/http/client.py", line 297, in begin
    version, status, reason = self._read_status()
  File "/usr/lib/python3.6/http/client.py", line 266, in _read_status
    raise RemoteDisconnected("Remote end closed connection without"
urllib3.exceptions.ProtocolError: ('Connection aborted.', RemoteDisconnected('Remote end closed connection without response',))
