Traceback (most recent call last):
  File "/usr/local/lib/python3.5/dist-packages/tensorflow/python/pywrap_tensorflow.py", line 41, in <module>
    from tensorflow.python.pywrap_tensorflow_internal import *
  File "/usr/local/lib/python3.5/dist-packages/tensorflow/python/pywrap_tensorflow_internal.py", line 28, in <module>
    _pywrap_tensorflow_internal = swig_import_helper()
  File "/usr/local/lib/python3.5/dist-packages/tensorflow/python/pywrap_tensorflow_internal.py", line 24, in swig_import_helper
    _mod = imp.load_module('_pywrap_tensorflow_internal', fp, pathname, description)
  File "/usr/lib/python3.5/imp.py", line 243, in load_module
    return load_dynamic(name, filename, file)
  File "/usr/lib/python3.5/imp.py", line 343, in load_dynamic
    return _load(spec)
ImportError: libcudnn.so.5: cannot open shared object file: No such file or directory

During handling of the above exception, another exception occurred:

Traceback (most recent call last):
  File "tests/neuralnet/test_ozone_tensorflow.py", line 11, in <module>
    import tensorflow as tf
  File "/usr/local/lib/python3.5/dist-packages/tensorflow/__init__.py", line 24, in <module>
    from tensorflow.python import *
  File "/usr/local/lib/python3.5/dist-packages/tensorflow/python/__init__.py", line 51, in <module>
    from tensorflow.python import pywrap_tensorflow
  File "/usr/local/lib/python3.5/dist-packages/tensorflow/python/pywrap_tensorflow.py", line 52, in <module>
    raise ImportError(msg)
ImportError: Traceback (most recent call last):
  File "/usr/local/lib/python3.5/dist-packages/tensorflow/python/pywrap_tensorflow.py", line 41, in <module>
    from tensorflow.python.pywrap_tensorflow_internal import *
  File "/usr/local/lib/python3.5/dist-packages/tensorflow/python/pywrap_tensorflow_internal.py", line 28, in <module>
    _pywrap_tensorflow_internal = swig_import_helper()
  File "/usr/local/lib/python3.5/dist-packages/tensorflow/python/pywrap_tensorflow_internal.py", line 24, in swig_import_helper
    _mod = imp.load_module('_pywrap_tensorflow_internal', fp, pathname, description)
  File "/usr/lib/python3.5/imp.py", line 243, in load_module
    return load_dynamic(name, filename, file)
  File "/usr/lib/python3.5/imp.py", line 343, in load_dynamic
    return _load(spec)
ImportError: libcudnn.so.5: cannot open shared object file: No such file or directory


Failed to load the native TensorFlow runtime.

See https://www.tensorflow.org/install/install_sources#common_installation_problems

for some common reasons and solutions.  Include the entire stack trace
above this error message when asking for help.
